Workbook

Sheet Raw data - Sites list
F1: =+SUBTOTAL(3,F3:F2443) -> 1216 | G1: =+SUBTOTAL(3,G3:G2443) -> 1216 | L1: =+SUBTOTAL(3,L3:L2443) -> 1216 | W1: Access Status | X1: (Plusieurs éléments)
A2: No | B2: Operator Site ID | C2: IHS ID | D2: Operator Site ID | E2: State | F2: Site Name | G2: Access Status | H2: Site Configuration | I2: Clusters | J2: Division | K2: Sub-Division | L2: Town | M2: Latitude | N2: Longitude | O2: Site Type
A3: 1 | B3: T2781 | C3: IHS_BAF_105 | D3: T2781 | E3: West | F3: PENKA MICHEL | G3: Normal Access | H3: Outdoor | I3: Bafoussam1 | J3: MENOUA | K3: PENKA MICHEL | L3: Bafoussam | M3: 5.46817 | N3: 10.2413 | O3: Greenfield | R3: Nombre de Access Status | S3: Étiquettes de colonnes | W3: Nombre de Town | X3: Étiquettes de colonnes | AB3: Nombre de Access Status | AC3: Étiquettes de colonnes
A4: =+A3+1 -> 2 | B4: CTR_297 | C4: IHS_YND_463 | D4: CTR_297 | E4: West | F4: Nomale | G4: Normal Access | H4: Outdoor | I4: Bafia | J4: Mbam et inoubou | K4: Ndikinimeki | L4: Bafoussam | M4: 4.7715 | N4: 10.90632 | O4: Greenfield | R4: Étiquettes de lignes | S4: Red Zone | T4: Green Zone | U4: Total général | W4: Region | X4: Greenfield | Y4: Rooftop | Z4: Total | AB4: Étiquettes de lignes | AC4: Red Zone | AD4: Red Zone - No Access | AE4: Red Zone -Vandalized | AF4: Total général
A5: =+A4+1 -> 3 | B5: OST_219 | C5: IHS_FBN_055 | D5: OST_219 | E5: West | F5: Ngbetnsouen | G5: Normal Access | H5: Outdoor | I5: Foumbot | J5: Noun | K5: Kouoptamo | L5: Bafoussam | M5: 5.63442 | N5: 10.53025 | O5: Greenfield | R5: Greenfield | S5: 394 | T5: 1443 | U5: 1837 | W5: Adamawa | X5: 133 | Y5: 6 | Z5: 139 | AB5: Greenfield | AC5: 394 | AD5: 17 | AE5: 4 | AF5: 415
A6: =+A5+1 -> 4 | B6: CTR_054 | C6: IHS_YND_445 | D6: CTR_054 | E6: West | F6: Ndoussan | G6: Normal Access | H6: Indoor | I6: Bafia | J6: Mbam et inoubou | K6: Kon-yambetta | L6: Bafoussam | M6: 4.822962 | N6: 11.175922 | O6: Greenfield | R6: Rooftop | S6: 28 | T6: 551 | U6: 579 | W6: Center | X6: 280 | Y6: 237 | Z6: 517 | AB6: Rooftop | AC6: 28 | AD6: 1 | AF6: 29
A7: =+A6+1 -> 5 | B7: OST_207 | C7: IHS_FBN_046 | D7: OST_207 | E7: West | F7: Ndoumken | G7: Normal Access | H7: Outdoor | I7: Foumbot | J7: Noun | K7: Kouoptamo | L7: Bafoussam | M7: 5.65799 | N7: 10.56229 | O7: Greenfield | R7: Total général | S7: 422 | T7: 1994 | U7: 2416 | W7: East | X7: 120 | Y7: 2 | Z7: 122 | AB7: Total général | AC7: 422 | AD7: 18 | AE7: 4 | AF7: 444
A8: =+A7+1 -> 6 | B8: OST_201 | C8: IHS_FBN_053 | D8: OST_201 | E8: West | F8: Mantoum Ville | G8: Normal Access | H8: Outdoor | I8: Foumban | J8: Noun | K8: Malantouen | L8: Bafoussam | M8: 5.656112 | N8: 11.172957 | O8: Greenfield | W8: Far North | X8: 195 | Y8: 7 | Z8: 202
A9: =+A8+1 -> 7 | B9: T1640 | C9: IHS_FBN_028 | D9: T1640 | E9: West | F9: Koupa Matapit | G9: Normal Access | H9: Outdoor | I9: Foumbot | J9: Noun | K9: Foumban | L9: Bafoussam | M9: 5.772444 | N9: 10.791806 | O9: Greenfield | W9: Littoral | X9: 246 | Y9: 261 | Z9: 507
A10: =+A9+1 -> 8 | B10: T2028 | C10: IHS_MBD_014 | D10: T2028 | E10: West | F10: GALIM EEC | G10: Red Zone | H10: Outdoor | I10: Bafoussam1 | J10: BAMBOUTOUS | K10: Galim | L10: Bafoussam | M10: 5.682028 | N10: 10.366139 | O10: Greenfield | W10: North | X10: 131 | Y10: 1 | Z10: 132
A11: =+A10+1 -> 9 | B11: OST_178 | C11: IHS_FBN_030 | D11: OST_178 | E11: West | F11: Founban Njintout II | G11: Normal Access | H11: Outdoor | I11: Foumban | J11: Noun | K11: Foumban | L11: Bafoussam | M11: 5.73795 | N11: 10.88407 | O11: Greenfield | W11: North West | X11: 182 | Y11: 10 | Z11: 192 | AB11: Étiquettes de lignes | AC11: Red Zone | AD11: Red Zone - No Access | AE11: Red Zone -Vandalized | AF11: Total général
A12: =+A11+1 -> 10 | B12: OST_136 | C12: IHS_FBN_101 | D12: OST_136 | E12: West | F12: Foumbot-Mangoum | G12: Normal Access | H12: Outdoor | I12: Foumbot | J12: Noun | K12: Foumbot | L12: Bafoussam | M12: 5.487811 | N12: 10.603086 | O12: Greenfield | W12: South | X12: 109 | Z12: 109 | AB12: Greenfield | AC12: 394 | AD12: 17 | AE12: 4 | AF12: 415
A13: =+A12+1 -> 11 | B13: OST_215 | C13: IHS_MBD_019 | D13: OST_215 | E13: West | F13: Bati | G13: Red Zone | H13: Outdoor | I13: Bafoussam1 | J13: BAMBOUTOUS | K13: Galim | L13: Bafoussam | M13: 5.667797 | N13: 10.447418 | O13: Greenfield | W13: South West | X13: 211 | Y13: 23 | Z13: 234 | AB13: Rooftop | AC13: 28 | AD13: 1 | AF13: 29
A14: =+A13+1 -> 12 | B14: T1478 | C14: IHS_BAF_063 | D14: T1478 | E14: West | F14: BANTOUM Lycee | G14: Normal Access | H14: Outdoor | I14: Bangangte | J14: Nde | K14: Bangangte | L14: Bafoussam | M14: 5.093755 | N14: 10.663701 | O14: Greenfield | W14: West | X14: 230 | Y14: 32 | Z14: 262 | AB14: Total général | AC14: 422 | AD14: 18 | AE14: 4 | AF14: 444
A15: =+A14+1 -> 13 | B15: NRO_050 | C15: IHS_BMD_310 | D15: NRO_050 | E15: West | F15: BANGOLAN | G15: Red Zone | H15: Outdoor | I15: Foumbot | J15: NGO-KETUNJIA | K15: Bangourain | L15: Bafoussam | M15: 5.593662 | N15: 10.61917 | O15: Greenfield | W15: Total | X15: 1837 | Y15: 579 | Z15: 2416
A16: =+A15+1 -> 14 | B16: T1580 | C16: IHS_FBN_027 | D16: T1580 | E16: West | F16: BANGANG FOKAM | G16: Normal Access | H16: Outdoor | I16: Bafoussam 2 | J16: Ndé | K16: Bangangte | L16: Bafoussam | M16: 5.249208 | N16: 10.511273 | O16: Greenfield
A17: =+A16+1 -> 15 | B17: T1589 | C17: IHS_FBN_026 | D17: T1589 | E17: West | F17: BANGAMBI | G17: Normal Access | H17: Outdoor | I17: Foumbot | J17: Noun | K17: Bangourain | L17: Bafoussam | M17: 5.826583 | N17: 10.732278 | O17: Greenfield
A18: =+A17+1 -> 16 | B18: OST_193 | C18: IHS_BAF_314 | D18: OST_193 | E18: West | F18: Banefo Baleng | G18: Normal Access | H18: Outdoor | I18: Bafoussam 3 | J18: MIFI | K18: BAFOUSSAM | L18: Bafoussam | M18: 5.58037 | N18: 10.40739 | O18: Greenfield
A19: =+A18+1 -> 17 | B19: OST_155 | C19: IHS_MBD_018 | D19: OST_155 | E19: West | F19: BAMENKOMBO | G19: Normal Access | H19: Outdoor | I19: Bafoussam1 | J19: MENOUA | K19: MBOUDA | L19: Bafoussam | M19: 5.600266 | N19: 10.325967 | O19: Greenfield
A20: =+A19+1 -> 18 | B20: OST_030 | C20: IHS_MBD_016 | D20: OST_030 | E20: West | F20: Bamendjing | G20: Red Zone | H20: Outdoor | I20: Bafoussam1 | J20: BAMBOUTOUS | K20: Galim | L20: Bafoussam | M20: 5.7009 | N20: 10.492 | O20: Greenfield
A21: =+A20+1 -> 19 | B21: T1498 | C21: IHS_BAF_042 | D21: T1498 | E21: West | F21: BAMEKA | G21: Normal Access | H21: Outdoor | I21: Bafoussam 2 | J21: Hauts-plateaux | K21: Baham | L21: Bafoussam | M21: 5.416224 | N21: 10.355382 | O21: Greenfield
A22: =+A21+1 -> 20 | B22: T2026 | C22: IHS_BAF_102 | D22: T2026 | E22: West | F22: BALOUM | G22: Normal Access | H22: Outdoor | I22: Bafoussam1 | J22: MIFI | K22: PENKA MICHEL | L22: Bafoussam | M22: 5.408253 | N22: 10.264578 | O22: Greenfield
A23: =+A22+1 -> 21 | B23: T1469 | C23: IHS_BAF_066 | D23: T1469 | E23: West | F23: BAKONG | G23: Normal Access | H23: Outdoor | I23: Bangangte | J23: Nde | K23: Bazou | L23: Bafoussam | M23: 5.08525 | N23: 10.488861 | O23: Greenfield
A24: =+A23+1 -> 22 | B24: T1483 | C24: IHS_BAF_047 | D24: T1483 | E24: West | F24: Bahouan | G24: Normal Access | H24: Outdoor | I24: Bafoussam 2 | J24: Hauts-plateaux | K24: Baham | L24: Bafoussam | M24: 5.351883 | N24: 10.340982 | O24: Greenfield
A25: =+A24+1 -> 23 | B25: OST_220 | C25: IHS_FBN_056 | D25: OST_220 | E25: West | F25: Ngambouo | G25: Normal Access | H25: Outdoor | I25: Foumbot | J25: Noun | K25: Kouoptamo | L25: Bafoussam | M25: 5.65988 | N25: 10.51872 | O25: Greenfield
A26: =+A25+1 -> 24 | B26: OST_189 | C26: IHS_FBN_044 | D26: OST_189 | E26: West | F26: Mfessang | G26: Normal Access | H26: Outdoor | I26: Foumbot | J26: Noun | K26: Foumbot | L26: Bafoussam | M26: 5.38566 | N26: 10.65691 | O26: Greenfield
A27: =+A26+1 -> 25 | B27: OST_200 | C27: IHS_FBN_041 | D27: OST_200 | E27: West | F27: MantoumVillage | G27: Normal Access | H27: Outdoor | I27: Foumban | J27: Noun | K27: Malantouen | L27: Bafoussam | M27: 5.647126 | N27: 11.152048 | O27: Greenfield | R27: Region | S27: Greenfield | T27: Rooftop | U27: Total
A28: =+A27+1 -> 26 | B28: OST_176 | C28: IHS_FBN_031 | D28: OST_176 | E28: West | F28: Foumban Njintout | G28: Normal Access | H28: Outdoor | I28: Foumban | J28: Noun | K28: Foumban | L28: Bafoussam | M28: 5.73305 | N28: 10.87373 | O28: Greenfield | R28: Adamawa | S28: 133 | T28: 6 | U28: 139
A29: =+A28+1 -> 27 | B29: OST_177 | C29: IHS_FBN_032 | D29: OST_177 | E29: West | F29: Fouban Njibam | G29: Normal Access | H29: Outdoor | I29: Foumban | J29: Noun | K29: Foumban | L29: Bafoussam | M29: 5.71516 | N29: 10.90575 | O29: Greenfield | R29: Center | S29: 280 | T29: 237 | U29: 517
A30: =+A29+1 -> 28 | B30: T1811 | C30: IHS_BAF_134 | D30: T1811 | E30: West | F30: Bafoussam Akwa | G30: Normal Access | H30: Outdoor | I30: Bafoussam 2 | J30: MIFI | K30: BAFOUSSAM | L30: Bafoussam | M30: 5.476651 | N30: 10.420191 | O30: Greenfield | R30: East | S30: 120 | T30: 2 | U30: 122
A31: =+A30+1 -> 29 | B31: T0148 | C31: IHS_YND_469 | D31: T0148 | E31: West | F31: Ndokohok | G31: Normal Access | H31: Indoor | I31: Bangangte | J31: Mbam et inoubou | K31: Ndikinimeki | L31: Bafoussam | M31: 4.869122 | N31: 10.817335 | O31: Greenfield | R31: Far North | S31: 195 | T31: 7 | U31: 202
A32: =+A31+1 -> 30 | B32: OST_026 | C32: IHS_MBD_015 | D32: OST_026 | E32: West | F32: Galim | G32: Red Zone | H32: Outdoor | I32: Bafoussam1 | J32: BAMBOUTOUS | K32: Galim | L32: Bafoussam | M32: 5.6951 | N32: 10.36 | O32: Greenfield | R32: Littoral | S32: 246 | T32: 261 | U32: 507
A33: =+A32+1 -> 31 | B33: T0303 | C33: IHS_FBN_014 | D33: T0303 | E33: West | F33: Magba | G33: Normal Access | H33: Indoor | I33: Foumban | J33: Noun | K33: Magba | L33: Bafoussam | M33: 5.97573 | N33: 11.20989 | O33: Greenfield | R33: North | S33: 131 | T33: 1 | U33: 132
A34: =+A33+1 -> 32 | B34: OST_058 | C34: IHS_FBN_023 | D34: OST_058 | E34: West | F34: Kouoptamo | G34: Red Zone | H34: Outdoor | I34: Foumbot | J34: Noun | K34: Kouoptamo | L34: Bafoussam | M34: 5.647889 | N34: 10.614667 | O34: Greenfield | R34: North West | S34: 182 | T34: 10 | U34: 192
A35: =+A34+1 -> 33 | B35: T0480 | C35: IHS_MBD_003 | D35: T0480 | E35: West | F35: Mbouda Town | G35: Normal Access | H35: Outdoor | I35: Bafoussam1 | J35: MENOUA | K35: MBOUDA | L35: Bafoussam | M35: 5.622493 | N35: 10.265157 | O35: Rooftop | R35: South | S35: 109 | U35: 109
A36: =+A35+1 -> 34 | B36: T0358 | C36: IHS_FBN_019 | D36: T0358 | E36: West | F36: Fosset | G36: Normal Access | H36: Indoor | I36: Foumbot | J36: Noun | K36: Foumbot | L36: Bafoussam | M36: 5.51873 | N36: 10.6676 | O36: Greenfield | R36: South West | S36: 211 | T36: 23 | U36: 234
A37: =+A36+1 -> 35 | B37: T1302 | C37: IHS_YND_472 | D37: T1302 | E37: West | F37: Nitoukou | G37: Normal Access | H37: Outdoor | I37: Bangangte | J37: Mbam et inoubou | K37: Nitoukou | L37: Bafoussam | M37: 4.627655 | N37: 10.875508 | O37: Greenfield | R37: West | S37: 230 | T37: 32 | U37: 262
A38: =+A37+1 -> 36 | B38: OST_195 | C38: IHS_FBN_052 | D38: OST_195 | E38: West | F38: Fochieya | G38: Normal Access | H38: Outdoor | I38: Foumbot | J38: Noun | K38: Foumbot | L38: Bafoussam | M38: 5.51738 | N38: 10.59631 | O38: Greenfield | R38: Total | S38: 1837 | T38: 579 | U38: 2416
A39: =+A38+1 -> 37 | B39: OST_087 | C39: IHS_FBN_007 | D39: OST_087 | E39: West | F39: Foumban-Ndjidare | G39: Normal Access | H39: Outdoor | I39: Foumban | J39: Noun | K39: Foumban | L39: Bafoussam | M39: 5.728286 | N39: 10.915294 | O39: Greenfield
A40: =+A39+1 -> 38 | B40: T1500 | C40: IHS_FBN_006 | D40: T1500 | E40: West | F40: FOUMBAN MANKA | G40: Normal Access | H40: Outdoor | I40: Foumban | J40: Noun | K40: Foumban | L40: Bafoussam | M40: 5.735056 | N40: 10.912417 | O40: Greenfield
...

Sheet Red Zone Sites 
G1: =+SUBTOTAL(3,G3:G446) -> 444
A2: No | B2: Operator Site ID | C2: IHS ID | D2: Operator Site ID | E2: State | F2: Site Name | G2: Access Status | H2: Site Configuration | I2: Clusters | J2: Division | K2: Sub-Division | L2: Town | M2: Latitude | N2: Longitude | O2: Site Type | Q2: Access Status | R2: Sites Count
A3: 1 | B3: T2028 | C3: IHS_MBD_014 | D3: T2028 | E3: West | F3: GALIM EEC | G3: Red Zone | H3: Outdoor | I3: Bafoussam1 | J3: BAMBOUTOUS | K3: Galim | L3: Bafoussam | M3: 5.682028 | N3: 10.366139 | O3: Greenfield | Q3: Red Zone | R3: 425
A4: =1+A3 -> 2 | B4: OST_215 | C4: IHS_MBD_019 | D4: OST_215 | E4: West | F4: Bati | G4: Red Zone | H4: Outdoor | I4: Bafoussam1 | J4: BAMBOUTOUS | K4: Galim | L4: Bafoussam | M4: 5.667797 | N4: 10.447418 | O4: Greenfield | Q4: Red Zone - No Access | R4: 17
A5: =1+A4 -> 3 | B5: NRO_050 | C5: IHS_BMD_310 | D5: NRO_050 | E5: West | F5: BANGOLAN | G5: Red Zone | H5: Outdoor | I5: Foumbot | J5: NGO-KETUNJIA | K5: Bangourain | L5: Bafoussam | M5: 5.593662 | N5: 10.61917 | O5: Greenfield | Q5: Red Zone -Vandalized | R5: 1
A6: =1+A5 -> 4 | B6: OST_030 | C6: IHS_MBD_016 | D6: OST_030 | E6: West | F6: Bamendjing | G6: Red Zone | H6: Outdoor | I6: Bafoussam1 | J6: BAMBOUTOUS | K6: Galim | L6: Bafoussam | M6: 5.7009 | N6: 10.492 | O6: Greenfield | Q6: Red Zone-No Access | R6: 1
A7: =1+A6 -> 5 | B7: OST_026 | C7: IHS_MBD_015 | D7: OST_026 | E7: West | F7: Galim | G7: Red Zone | H7: Outdoor | I7: Bafoussam1 | J7: BAMBOUTOUS | K7: Galim | L7: Bafoussam | M7: 5.6951 | N7: 10.36 | O7: Greenfield | Q7: Total général | R7: 444
A8: =1+A7 -> 6 | B8: OST_058 | C8: IHS_FBN_023 | D8: OST_058 | E8: West | F8: Kouoptamo | G8: Red Zone | H8: Outdoor | I8: Foumbot | J8: Noun | K8: Kouoptamo | L8: Bafoussam | M8: 5.647889 | N8: 10.614667 | O8: Greenfield
A9: =1+A8 -> 7 | B9: OST_090 | C9: IHS_FBN_018 | D9: OST_090 | E9: West | F9: Bangourain | G9: Red Zone | H9: Outdoor | I9: Foumbot | J9: Noun | K9: Bangourain | L9: Bafoussam | M9: 5.875667 | N9: 10.673917 | O9: Greenfield
A10: =1+A9 -> 8 | B10: T0359 | C10: IHS_MBD_013 | D10: T0359 | E10: West | F10: Bamendjing | G10: Red Zone | H10: Indoor | I10: Bafoussam1 | J10: BAMBOUTOUS | K10: Galim | L10: Bafoussam | M10: 5.71364 | N10: 10.446389 | O10: Greenfield | Q10: Access Status | R10: Sites Count
A11: =1+A10 -> 9 | B11: NRO_030 | C11: IHS_BMD_206 | D11: NRO_030 | E11: North West | F11: Zhoa | G11: Red Zone | H11: Outdoor | I11: Bafut | J11: MENCHUM | K11: Zhoa | L11: Bamenda | M11: 6.5311833 | N11: 10.2 | O11: Greenfield | Q11: Red Zone | R11: 425
A12: =1+A11 -> 10 | B12: T1668 | C12: IHS_BMD_2217 | D12: T1668 | E12: North West | F12: TATUM | G12: Red Zone | H12: Outdoor | I12: Nkambe | J12: BUI | K12: Nkum | L12: Bamenda | M12: 6.344511 | N12: 10.770329 | O12: Greenfield | Q12: Red Zone - No Access | R12: 17
A13: =1+A12 -> 11 | B13: T1475 | C13: IHS_BMD_078 | D13: T1475 | E13: North West | F13: TADU | G13: Red Zone | H13: Outdoor | I13: Kumbo | J13: BUI | K13: Tadu | L13: Bamenda | M13: 6.23718 | N13: 10.589529 | O13: Greenfield | Q13: Red Zone -Vandalized | R13: 1
A14: =1+A13 -> 12 | B14: T2816 | C14: IHS_BMD_0065 | D14: T2816 | E14: North West | F14: Small Babanki | G14: Red Zone - No Access | H14: Outdoor | I14: Bamenda 1 | J14: MEZAM | K14: Tubah | L14: Bamenda | M14: 5.949333 | N14: 10.326583 | O14: Greenfield | Q14: Red Zone-No Access | R14: 1
A15: =1+A14 -> 13 | B15: NRO_048 | C15: IHS_BMD_321 | D15: NRO_048 | E15: North West | F15: Sabga | G15: Red Zone | H15: Outdoor | I15: Bamenda 1 | J15: MEZAM | K15: Tubah | L15: Bamenda | M15: 6.013814 | N15: 10.320172 | O15: Greenfield | Q15: Total général | R15: 444
A16: =1+A15 -> 14 | B16: T2836 | C16: IHS_BMD_2214 | D16: T2836 | E16: North West | F16: Pinyin Ngali | G16: Red Zone | H16: OutDoor | I16: Bamenda 2 | J16: MEZAM | K16: Tubah | L16: Bamenda | M16: 5.807455 | N16: 10.066275 | O16: Greenfield
A17: =1+A16 -> 15 | B17: T2766 | C17: IHS_BMD_2216 | D17: T2766 | E17: North West | F17: NKOR | G17: Red Zone | H17: Outdoor | I17: Nkambe | J17: Bui | K17: Nkor | L17: Bamenda | M17: 6.383265 | N17: 10.584665 | O17: Greenfield
A18: =1+A17 -> 16 | B18: T1473 | C18: IHS_BMD_066 | D18: T1473 | E18: North West | F18: Nkar | G18: Red Zone | H18: Outdoor | I18: Kumbo | J18: Bui | K18: Jakiri | L18: Bamenda | M18: 6.0944444 | N18: 10.637861 | O18: Greenfield
A19: =1+A18 -> 17 | B19: T1503 | C19: IHS_BMD_061 | D19: T1503 | E19: North West | F19: Njikwa town | G19: Red Zone | H19: Outdoor | I19: Bamenda 2 | J19: Momo | K19: Njikwa | L19: Bamenda | M19: 6.129225 | N19: 9.8565167 | O19: Greenfield
A20: =1+A19 -> 18 | B20: T2823 | C20: IHS_BMD_2224 | D20: T2823 | E20: North West | F20: Nchum | G20: Red Zone | H20: Outdoor | I20: Bafut | J20: MEZAM | K20: Bafut | L20: Bamenda | M20: 6.111643 | N20: 10.121766 | O20: Greenfield
A21: =1+A20 -> 19 | B21: NRO_057 | C21: IHS_BMD_312 | D21: NRO_057 | E21: North West | F21: Mbonso | G21: Red Zone | H21: Outdoor | I21: Nkambe | J21: Bui | K21: mbiame | L21: Bamenda | M21: 6.261408 | N21: 10.946337 | O21: Greenfield
A22: =1+A21 -> 20 | B22: T1465 | C22: IHS_BMD_087 | D22: T1465 | E22: North West | F22: MBIYEH | G22: Red Zone | H22: Outdoor | I22: Nkambe | J22: Donga Mantoum | K22: Ndu | L22: Bamenda | M22: 6.4542222 | N22: 10.754222 | O22: Greenfield
A23: =1+A22 -> 21 | B23: NRO_236 | C23: IHS_BMD_091 | D23: NRO_236 | E23: North West | F23: Mbiame | G23: Red Zone | H23: Outdoor | I23: Kumbo | J23: Bui | K23: Mbiame | L23: Bamenda | M23: 6.188547 | N23: 10.849605 | O23: Greenfield
A24: =1+A23 -> 22 | B24: T1831 | C24: IHS_BMD_2250 | D24: T1831 | E24: North West | F24: Mbengwi Water Tank | G24: Red Zone | H24: Outdoor | I24: Bamenda 2 | J24: Momo | K24: Mbengwi | L24: Bamenda | M24: 5.968124 | N24: 10.036383 | O24: Greenfield
A25: =1+A24 -> 23 | B25: T1488 | C25: IHS_BMD_034 | D25: T1488 | E25: North West | F25: Mbengwi Mile 17 | G25: Red Zone | H25: Outdoor | I25: Bamenda 2 | J25: Momo | K25: Mbengwi | L25: Bamenda | M25: 6.001216 | N25: 10.020552 | O25: Greenfield
A26: =1+A25 -> 24 | B26: T1167 | C26: IHS_BMD_016 | D26: T1167 | E26: North West | F26: MBATU | G26: Red Zone | H26: Outdoor | I26: Bamenda 2 | J26: MEZAM | K26: Bamenda 2 | L26: Bamenda | M26: 5.93473 | N26: 10.13917 | O26: Greenfield
A27: =1+A26 -> 25 | B27: NRO_044 | C27: IHS_BMD_316 | D27: NRO_044 | E27: North West | F27: Lassin | G27: Red Zone | H27: Outdoor | I27: Nkambe | J27: Bui | K27: Nkor | L27: Bamenda | M27: 6.442286 | N27: 10.620562 | O27: Greenfield
... A193: =1+A192 -> 191 | B193: T1581 | C193: IHS_BUA_160 | D193: T1581 | E193: South West | F193: Bai Kuke | G193: Red Zone | H193: Outdoor | I193: Ekondo Titi | J193: FAKO | K193: Mbonge | L193: Buea | M193: 4.456883 | N193: 9.143987 | O193: Greenfield
A194: =1+A193 -> 192 | B194: T1781-1 | C194: IHS_BUA_034 | D194: T1781-1 | E194: South West | F194: Ekona II | G194: Red Zone - No Access | H194: Outdoor | I194: Buea | K194: Ekona | L194: Buea | M194: 4.229944 | N194: 9.330528 | O194: Rooftop
A195: =1+A194 -> 193 | B195: T1725 | C195: IHS_BUA_131 | D195: T1725 | E195: South West | F195: MILE16 BOLIFAMBA | G195: Red Zone | H195: Outdoor | I195: Buea | J195: FAKO | K195: BUEA | L195: Buea | M195: 4.139806 | N195: 9.311917 | O195: Greenfield
A196: =1+A195 -> 194 | B196: T1310 | C196: IHS_BUA_164 | D196: T1310 | E196: South West | F196: Malende | G196: Red Zone | H196: Outdoor | I196: Buea | J196: FAKO | K196: Muyuka | L196: Buea | M196: 4.343306 | N196: 9.430944 | O196: Greenfield
A197: =1+A196 -> 195 | B197: T0300 | C197: IHS_BUA_017 | D197: T0300 | E197: South West | F197: Bomaka Mile 17 | G197: Red Zone | H197: Indoor | I197: Buea | J197: FAKO | K197: Buea | L197: Buea | M197: 4.151835 | N197: 9.299842 | O197: Greenfield
A198: =1+A197 -> 196 | B198: T0419 | C198: IHS_BUA_001 | D198: T0419 | E198: South West | F198: Buea University | G198: Red Zone | H198: Indoor | I198: Buea | J198: FAKO | K198: Buea | L198: Buea | M198: 4.158132 | N198: 9.270084 | O198: Rooftop
A199: =1+A198 -> 197 | B199: T0559 | C199: IHS_BUA_033 | D199: T0559 | E199: South West | F199: Ekona | G199: Red Zone | H199: Outdoor | I199: Buea | J199: FAKO | K199: Ekona | L199: Buea | M199: 4.22679 | N199: 9.33914 | O199: Greenfield
A200: =1+A199 -> 198 | B200: T0671 | C200: IHS_BUA_028 | D200: T0671 | E200: South West | F200: Mile 14 | G200: Red Zone | H200: Outdoor | I200: Buea | J200: FAKO | K200: Buea | L200: Buea | M200: 4.123209 | N200: 9.309349 | O200: Greenfield
A201: =1+A200 -> 199 | B201: SUO_004 | C201: IHS_BUA_037 | D201: SUO_004 | E201: South West | F201: Tiko | G201: Red Zone | H201: Indoor | I201: Mutenguene | J201: FAKO | K201: TIKO | L201: Buea | M201: 4.075187 | N201: 9.367831 | O201: Greenfield
A202: =1+A201 -> 200 | B202: T0438 | C202: IHS_BUA_015 | D202: T0438 | E202: South West | F202: Bokwango | G202: Red Zone | H202: Outdoor | I202: Buea | J202: FAKO | K202: Buea | L202: Buea | M202: 4.137215 | N202: 9.229888 | O202: Greenfield
A203: =1+A202 -> 201 | B203: T0069 | C203: IHS_BUA_006 | D203: T0069 | E203: South West | F203: Great Soppo | G203: Red Zone | H203: Indoor | I203: Buea | J203: FAKO | K203: Buea | L203: Buea | M203: 4.157996 | N203: 9.254179 | O203: Greenfield
A204: =1+A203 -> 202 | B204: SUO_007 | C204: IHS_BUA_002 | D204: SUO_007 | E204: South West | F204: Buea-Orange | G204: Red Zone | H204: Indoor | I204: Buea | J204: FAKO | K204: Buea | L204: Buea | M204: 4.159561 | N204: 9.269411 | O204: Greenfield
A205: =1+A204 -> 203 | B205: SUO_077 | C205: IHS_BUA_021 | D205: SUO_077 | E205: South West | F205: Buea-David-Square | G205: Red Zone | H205: Outdoor | I205: Buea | J205: FAKO | K205: Buea | L205: Buea | M205: 4.167639 | N205: 9.301833 | O205: Rooftop
...

Sheet Sites Audit Plan  
A1: IHS SITES AUDIT SUMMARY PLAN
A3: Region | B3: Greenfield | C3: Rooftop | D3: Total | E3: SBC | F3: Base line per day | G3: Teams planned | H3: Weekly Target | I3: Number of weeks required | J3: Planned Start date | K3: Planned End date
A4: Adamawa | B4: 133 | C4: 6 | D4: 139 | E4: SBC1 | F4: 2 | G4: 2 | H4: =+F4*G4*6 -> 24 | I4: =+D4/H4 -> 5.7916667 | J4: =+J8+3 -> 46252 | K4: 46291
A5: Center | B5: 280 | C5: 237 | D5: 517 | E5: SBC1 & SBC2 | F5: 3 | G5: 5 | H5: =+F5*G5*6 -> 90 | I5: =+D5/H5 -> 5.7444444 | J5: 46249 | K5: 46289.211
A6: East | B6: 120 | C6: 2 | D6: 122 | E6: SBC1 | F6: 2 | G6: 2 | H6: =+F6*G6*6 -> 24 | I6: =+D6/H6 -> 5.0833333 | J6: =+J8+2 -> 46251 | K6: 46286.583
A7: Far North | B7: 195 | C7: 7 | D7: 202 | E7: SBC2 | F7: 1 | G7: 6 | H7: =+F7*G7*6 -> 36 | I7: =+D7/H7 -> 5.6111111 | J7: =+J8+5 -> 46254 | K7: 46292
A8: Littoral | B8: 246 | C8: 261 | D8: 507 | E8: Cluenatic (Patrick Ehimeare) | F8: 3 | G8: 5 | H8: =+F8*G8*6 -> 90 | I8: =+D8/H8 -> 5.6333333 | J8: 46249 | K8: 46289
A9: North | B9: 131 | C9: 1 | D9: 132 | E9: SBC2 | F9: 2 | G9: 2 | H9: =+F9*G9*6 -> 24 | I9: =+D9/H9 -> 5.5 | J9: =+J8+4 -> 46253 | K9: 46290
A10: North West | B10: 182 | C10: 10 | D10: 192 | E10: SBC3 | F10: 1 | G10: 5 | H10: =+F10*G10*6 -> 30 | I10: =+D10/H10 -> 6.4 | J10: =+J8+2 -> 46251 | K10: 46294
A11: South | B11: 109 | D11: 109 | E11: SBC2 | F11: 1 | G11: 4 | H11: =+F11*G11*6 -> 24 | I11: =+D11/H11 -> 4.5416667 | J11: =+J8+2 -> 46251 | K11: =+J11+I11*7 -> 46282.792
A12: South West | B12: 211 | C12: 23 | D12: 234 | E12: SBC3 | F12: 2 | G12: 5 | H12: =+F12*G12*6 -> 60 | I12: =+D12/H12 -> 3.9 | J12: =+J8+2 -> 46251 | K12: 46277
A13: West | B13: 230 | C13: 32 | D13: 262 | E13: SBC1 | F13: 2 | G13: 4 | H13: =+F13*G13*6 -> 48 | I13: =+D13/H13 -> 5.4583333 | J13: =+J8+2 -> 46251 | K13: 46288
A14: Total | B14: =+SUBTOTAL(9,B4:B13) -> 1837 | C14: =+SUBTOTAL(9,C4:C13) -> 579 | D14: =+SUBTOTAL(9,D4:D13) -> 2416 | F14: =SUBTOTAL(101,F4:F13) -> 1.9 | G14: =+SUBTOTAL(9,G4:G13) -> 40 | H14: =+SUBTOTAL(9,H4:H13) -> 450 | I14: =SUBTOTAL(101,I4:I13) -> 5.3663889
A16: Total Number of Sites | B16: =+D14 -> 2416
A17: Number of Teams | B17: =+G14 -> 40
A18: Average Site Audit per day | B18: =+F14 -> 1.9
A19: Weekly target | B19: =+H14 -> 450
A20: Project Start date | B20: =+J8 -> 46249
A21: Project End Date | B21: =+K10 -> 46294

Sheet PIP
A1: IHS SITE AUDIT PIP
A3: Region | B3: Total number of Sites | C3: SBC | D3: Weekly target | E3: Week 1 | K3: Week 2 | Q3: Week 3 | W3: Week 4 | AC3: Week 5 | AI3: Week 6 | AO3: Week 7 | AU3: Week 8
E4: 46249 | F4: 46250 | G4: 46251 | H4: 46252 | I4: 46253 | J4: 46254 | K4: 46255 | L4: 46256 | M4: 46257 | N4: 46258 | O4: 46259 | P4: 46260 | Q4: 46261 | R4: 46262 | S4: 46263 | T4: 46264 | U4: 46265 | V4: 46266 | W4: 46267 | X4: 46268 | Y4: 46269 | Z4: 46270 | AA4: 46271 | AB4: 46272 | AC4: 46273 | AD4: 46274 | AE4: 46275 | AF4: 46276 | AG4: 46277 | AH4: 46278 | AI4: 46279 | AJ4: 46280 | AK4: 46281 | AL4: 46282 | AM4: 46283 | AN4: 46284 | AO4: 46285 | AP4: 46286 | AQ4: 46287 | AR4: 46288 | AS4: 46289 | AT4: 46290 | AU4: 46291 | AV4: 46292 | AW4: 46293 | AX4: 46294 | AY4: 46295 | AZ4: 46296
A5: Adamawa | B5: =+'Sites Audit Plan '!D4 -> 139 | C5: =+'Sites Audit Plan '!E4 -> SBC1 | D5: =+'Sites Audit Plan '!H4 -> 24 | H5: =+'Sites Audit Plan '!$F$4*'Sites Audit Plan '!$G$4 -> 4 | I5: =+'Sites Audit Plan '!$F$4*'Sites Audit Plan '!$G$4 -> 4 | J5: =+'Sites Audit Plan '!$F$4*'Sites Audit Plan '!$G$4 -> 4 | K5: =+'Sites Audit Plan '!$F$4*'Sites Audit Plan '!$G$4 -> 4 | L5: =+'Sites Audit Plan '!$F$4*'Sites Audit Plan '!$G$4 -> 4 | N5: =+'Sites Audit Plan '!$F$4*'Sites Audit Plan '!$G$4 -> 4 | O5: =+'Sites Audit Plan '!$F$4*'Sites Audit Plan '!$G$4 -> 4 | P5: =+'Sites Audit Plan '!$F$4*'Sites Audit Plan '!$G$4 -> 4 | Q5: =+'Sites Audit Plan '!$F$4*'Sites Audit Plan '!$G$4 -> 4 | R5: =+'Sites Audit Plan '!$F$4*'Sites Audit Plan '!$G$4 -> 4 | S5: =+'Sites Audit Plan '!$F$4*'Sites Audit Plan '!$G$4 -> 4 | U5: =+'Sites Audit Plan '!$F$4*'Sites Audit Plan '!$G$4 -> 4 | V5: =+'Sites Audit Plan '!$F$4*'Sites Audit Plan '!$G$4 -> 4 | W5: =+'Sites Audit Plan '!$F$4*'Sites Audit Plan '!$G$4 -> 4 | X5: =+'Sites Audit Plan '!$F$4*'Sites Audit Plan '!$G$4 -> 4 | Y5: =+'Sites Audit Plan '!$F$4*'Sites Audit Plan '!$G$4 -> 4 | Z5: =+'Sites Audit Plan '!$F$4*'Sites Audit Plan '!$G$4 -> 4 | AB5: =+'Sites Audit Plan '!$F$4*'Sites Audit Plan '!$G$4 -> 4 | AC5: =+'Sites Audit Plan '!$F$4*'Sites Audit Plan '!$G$4 -> 4 | AD5: =+'Sites Audit Plan '!$F$4*'Sites Audit Plan '!$G$4 -> 4 | AE5: =+'Sites Audit Plan '!$F$4*'Sites Audit Plan '!$G$4 -> 4 | AF5: =+'Sites Audit Plan '!$F$4*'Sites Audit Plan '!$G$4 -> 4 | AG5: =+'Sites Audit Plan '!$F$4*'Sites Audit Plan '!$G$4 -> 4 | AI5: =+'Sites Audit Plan '!$F$4*'Sites Audit Plan '!$G$4 -> 4 | AJ5: =+'Sites Audit Plan '!$F$4*'Sites Audit Plan '!$G$4 -> 4 | AK5: =+'Sites Audit Plan '!$F$4*'Sites Audit Plan '!$G$4 -> 4 | AL5: =+'Sites Audit Plan '!$F$4*'Sites Audit Plan '!$G$4 -> 4 | AM5: =+'Sites Audit Plan '!$F$4*'Sites Audit Plan '!$G$4 -> 4 | AN5: =+'Sites Audit Plan '!$F$4*'Sites Audit Plan '!$G$4 -> 4 | AP5: =+'Sites Audit Plan '!$F$4*'Sites Audit Plan '!$G$4 -> 4 | AQ5: =+'Sites Audit Plan '!$F$4*'Sites Audit Plan '!$G$4 -> 4 | AR5: =+'Sites Audit Plan '!$F$4*'Sites Audit Plan '!$G$4 -> 4 | AS5: =+'Sites Audit Plan '!$F$4*'Sites Audit Plan '!$G$4 -> 4 | AT5: =+'Sites Audit Plan '!$F$4*'Sites Audit Plan '!$G$4 -> 4 | AU5: 3
A6: Center | B6: =+'Sites Audit Plan '!D5 -> 517 | C6: =+'Sites Audit Plan '!E5 -> SBC1 & SBC2 | D6: =+'Sites Audit Plan '!H5 -> 90 | E6: =+'Sites Audit Plan '!$F$5*'Sites Audit Plan '!$G$5 -> 15 | G6: =+'Sites Audit Plan '!$F$5*'Sites Audit Plan '!$G$5 -> 15 | H6: =+'Sites Audit Plan '!$F$5*'Sites Audit Plan '!$G$5 -> 15 | I6: =+'Sites Audit Plan '!$F$5*'Sites Audit Plan '!$G$5 -> 15 | J6: =+'Sites Audit Plan '!$F$5*'Sites Audit Plan '!$G$5 -> 15 | K6: =+'Sites Audit Plan '!$F$5*'Sites Audit Plan '!$G$5 -> 15 | L6: =+'Sites Audit Plan '!$F$5*'Sites Audit Plan '!$G$5 -> 15 | N6: =+'Sites Audit Plan '!$F$5*'Sites Audit Plan '!$G$5 -> 15 | O6: =+'Sites Audit Plan '!$F$5*'Sites Audit Plan '!$G$5 -> 15 | P6: =+'Sites Audit Plan '!$F$5*'Sites Audit Plan '!$G$5 -> 15 | Q6: =+'Sites Audit Plan '!$F$5*'Sites Audit Plan '!$G$5 -> 15 | R6: =+'Sites Audit Plan '!$F$5*'Sites Audit Plan '!$G$5 -> 15 | S6: =+'Sites Audit Plan '!$F$5*'Sites Audit Plan '!$G$5 -> 15 | U6: =+'Sites Audit Plan '!$F$5*'Sites Audit Plan '!$G$5 -> 15 | V6: =+'Sites Audit Plan '!$F$5*'Sites Audit Plan '!$G$5 -> 15 | W6: =+'Sites Audit Plan '!$F$5*'Sites Audit Plan '!$G$5 -> 15 | X6: =+'Sites Audit Plan '!$F$5*'Sites Audit Plan '!$G$5 -> 15 | Y6: =+'Sites Audit Plan '!$F$5*'Sites Audit Plan '!$G$5 -> 15 | Z6: =+'Sites Audit Plan '!$F$5*'Sites Audit Plan '!$G$5 -> 15 | AB6: =+'Sites Audit Plan '!$F$5*'Sites Audit Plan '!$G$5 -> 15 | AC6: =+'Sites Audit Plan '!$F$5*'Sites Audit Plan '!$G$5 -> 15 | AD6: =+'Sites Audit Plan '!$F$5*'Sites Audit Plan '!$G$5 -> 15 | AE6: =+'Sites Audit Plan '!$F$5*'Sites Audit Plan '!$G$5 -> 15 | AF6: =+'Sites Audit Plan '!$F$5*'Sites Audit Plan '!$G$5 -> 15 | AG6: =+'Sites Audit Plan '!$F$5*'Sites Audit Plan '!$G$5 -> 15 | AI6: =+'Sites Audit Plan '!$F$5*'Sites Audit Plan '!$G$5 -> 15 | AJ6: =+'Sites Audit Plan '!$F$5*'Sites Audit Plan '!$G$5 -> 15 | AK6: =+'Sites Audit Plan '!$F$5*'Sites Audit Plan '!$G$5 -> 15 | AL6: =+'Sites Audit Plan '!$F$5*'Sites Audit Plan '!$G$5 -> 15 | AM6: =+'Sites Audit Plan '!$F$5*'Sites Audit Plan '!$G$5 -> 15 | AN6: =+'Sites Audit Plan '!$F$5*'Sites Audit Plan '!$G$5 -> 15 | AP6: =+'Sites Audit Plan '!$F$5*'Sites Audit Plan '!$G$5 -> 15 | AQ6: =+'Sites Audit Plan '!$F$5*'Sites Audit Plan '!$G$5 -> 15 | AR6: =+'Sites Audit Plan '!$F$5*'Sites Audit Plan '!$G$5 -> 15 | AS6: 7
A7: East | B7: =+'Sites Audit Plan '!D6 -> 122 | C7: =+'Sites Audit Plan '!E6 -> SBC1 | D7: =+'Sites Audit Plan '!H6 -> 24 | G7: =+'Sites Audit Plan '!$F$6*'Sites Audit Plan '!$G$6 -> 4 | H7: =+'Sites Audit Plan '!$F$6*'Sites Audit Plan '!$G$6 -> 4 | I7: =+'Sites Audit Plan '!$F$6*'Sites Audit Plan '!$G$6 -> 4 | J7: =+'Sites Audit Plan '!$F$6*'Sites Audit Plan '!$G$6 -> 4 | K7: =+'Sites Audit Plan '!$F$6*'Sites Audit Plan '!$G$6 -> 4 | L7: =+'Sites Audit Plan '!$F$6*'Sites Audit Plan '!$G$6 -> 4 | N7: =+'Sites Audit Plan '!$F$6*'Sites Audit Plan '!$G$6 -> 4 | O7: =+'Sites Audit Plan '!$F$6*'Sites Audit Plan '!$G$6 -> 4 | P7: =+'Sites Audit Plan '!$F$6*'Sites Audit Plan '!$G$6 -> 4 | Q7: =+'Sites Audit Plan '!$F$6*'Sites Audit Plan '!$G$6 -> 4 | R7: =+'Sites Audit Plan '!$F$6*'Sites Audit Plan '!$G$6 -> 4 | S7: =+'Sites Audit Plan '!$F$6*'Sites Audit Plan '!$G$6 -> 4 | U7: =+'Sites Audit Plan '!$F$6*'Sites Audit Plan '!$G$6 -> 4 | V7: =+'Sites Audit Plan '!$F$6*'Sites Audit Plan '!$G$6 -> 4 | W7: =+'Sites Audit Plan '!$F$6*'Sites Audit Plan '!$G$6 -> 4 | X7: =+'Sites Audit Plan '!$F$6*'Sites Audit Plan '!$G$6 -> 4 | Y7: =+'Sites Audit Plan '!$F$6*'Sites Audit Plan '!$G$6 -> 4 | Z7: =+'Sites Audit Plan '!$F$6*'Sites Audit Plan '!$G$6 -> 4 | AB7: =+'Sites Audit Plan '!$F$6*'Sites Audit Plan '!$G$6 -> 4 | AC7: =+'Sites Audit Plan '!$F$6*'Sites Audit Plan '!$G$6 -> 4 | AD7: =+'Sites Audit Plan '!$F$6*'Sites Audit Plan '!$G$6 -> 4 | AE7: =+'Sites Audit Plan '!$F$6*'Sites Audit Plan '!$G$6 -> 4 | AF7: =+'Sites Audit Plan '!$F$6*'Sites Audit Plan '!$G$6 -> 4 | AG7: =+'Sites Audit Plan '!$F$6*'Sites Audit Plan '!$G$6 -> 4 | AI7: =+'Sites Audit Plan '!$F$6*'Sites Audit Plan '!$G$6 -> 4 | AJ7: =+'Sites Audit Plan '!$F$6*'Sites Audit Plan '!$G$6 -> 4 | AK7: =+'Sites Audit Plan '!$F$6*'Sites Audit Plan '!$G$6 -> 4 | AL7: =+'Sites Audit Plan '!$F$6*'Sites Audit Plan '!$G$6 -> 4 | AM7: =+'Sites Audit Plan '!$F$6*'Sites Audit Plan '!$G$6 -> 4 | AN7: =+'Sites Audit Plan '!$F$6*'Sites Audit Plan '!$G$6 -> 4 | AP7: 2
A8: Far North | B8: =+'Sites Audit Plan '!D7 -> 202 | C8: =+'Sites Audit Plan '!E7 -> SBC2 | D8: =+'Sites Audit Plan '!H7 -> 36 | J8: =+'Sites Audit Plan '!$F$7*'Sites Audit Plan '!$G$7 -> 6 | K8: =+'Sites Audit Plan '!$F$7*'Sites Audit Plan '!$G$7 -> 6 | L8: =+'Sites Audit Plan '!$F$7*'Sites Audit Plan '!$G$7 -> 6 | N8: =+'Sites Audit Plan '!$F$7*'Sites Audit Plan '!$G$7 -> 6 | O8: =+'Sites Audit Plan '!$F$7*'Sites Audit Plan '!$G$7 -> 6 | P8: =+'Sites Audit Plan '!$F$7*'Sites Audit Plan '!$G$7 -> 6 | Q8: =+'Sites Audit Plan '!$F$7*'Sites Audit Plan '!$G$7 -> 6 | R8: =+'Sites Audit Plan '!$F$7*'Sites Audit Plan '!$G$7 -> 6 | S8: =+'Sites Audit Plan '!$F$7*'Sites Audit Plan '!$G$7 -> 6 | U8: =+'Sites Audit Plan '!$F$7*'Sites Audit Plan '!$G$7 -> 6 | V8: =+'Sites Audit Plan '!$F$7*'Sites Audit Plan '!$G$7 -> 6 | W8: =+'Sites Audit Plan '!$F$7*'Sites Audit Plan '!$G$7 -> 6 | X8: =+'Sites Audit Plan '!$F$7*'Sites Audit Plan '!$G$7 -> 6 | Y8: =+'Sites Audit Plan '!$F$7*'Sites Audit Plan '!$G$7 -> 6 | Z8: =+'Sites Audit Plan '!$F$7*'Sites Audit Plan '!$G$7 -> 6 | AB8: =+'Sites Audit Plan '!$F$7*'Sites Audit Plan '!$G$7 -> 6 | AC8: =+'Sites Audit Plan '!$F$7*'Sites Audit Plan '!$G$7 -> 6 | AD8: =+'Sites Audit Plan '!$F$7*'Sites Audit Plan '!$G$7 -> 6 | AE8: =+'Sites Audit Plan '!$F$7*'Sites Audit Plan '!$G$7 -> 6 | AF8: =+'Sites Audit Plan '!$F$7*'Sites Audit Plan '!$G$7 -> 6 | AG8: =+'Sites Audit Plan '!$F$7*'Sites Audit Plan '!$G$7 -> 6 | AI8: =+'Sites Audit Plan '!$F$7*'Sites Audit Plan '!$G$7 -> 6 | AJ8: =+'Sites Audit Plan '!$F$7*'Sites Audit Plan '!$G$7 -> 6 | AK8: =+'Sites Audit Plan '!$F$7*'Sites Audit Plan '!$G$7 -> 6 | AL8: =+'Sites Audit Plan '!$F$7*'Sites Audit Plan '!$G$7 -> 6 | AM8: =+'Sites Audit Plan '!$F$7*'Sites Audit Plan '!$G$7 -> 6 | AN8: =+'Sites Audit Plan '!$F$7*'Sites Audit Plan '!$G$7 -> 6 | AP8: =+'Sites Audit Plan '!$F$7*'Sites Audit Plan '!$G$7 -> 6 | AQ8: =+'Sites Audit Plan '!$F$7*'Sites Audit Plan '!$G$7 -> 6 | AR8: =+'Sites Audit Plan '!$F$7*'Sites Audit Plan '!$G$7 -> 6 | AS8: =+'Sites Audit Plan '!$F$7*'Sites Audit Plan '!$G$7 -> 6 | AT8: =+'Sites Audit Plan '!$F$7*'Sites Audit Plan '!$G$7 -> 6 | AU8: =+'Sites Audit Plan '!$F$7*'Sites Audit Plan '!$G$7 -> 6 | AV8: 4
A9: Littoral | B9: =+'Sites Audit Plan '!D8 -> 507 | C9: SBC4 | D9: =+'Sites Audit Plan '!H8 -> 90 | E9: =+'Sites Audit Plan '!$F$8*'Sites Audit Plan '!$G$8 -> 15 | G9: =+'Sites Audit Plan '!$F$8*'Sites Audit Plan '!$G$8 -> 15 | H9: =+'Sites Audit Plan '!$F$8*'Sites Audit Plan '!$G$8 -> 15 | I9: =+'Sites Audit Plan '!$F$8*'Sites Audit Plan '!$G$8 -> 15 | J9: =+'Sites Audit Plan '!$F$8*'Sites Audit Plan '!$G$8 -> 15 | K9: =+'Sites Audit Plan '!$F$8*'Sites Audit Plan '!$G$8 -> 15 | L9: =+'Sites Audit Plan '!$F$8*'Sites Audit Plan '!$G$8 -> 15 | N9: =+'Sites Audit Plan '!$F$8*'Sites Audit Plan '!$G$8 -> 15 | O9: =+'Sites Audit Plan '!$F$8*'Sites Audit Plan '!$G$8 -> 15 | P9: =+'Sites Audit Plan '!$F$8*'Sites Audit Plan '!$G$8 -> 15 | Q9: =+'Sites Audit Plan '!$F$8*'Sites Audit Plan '!$G$8 -> 15 | R9: =+'Sites Audit Plan '!$F$8*'Sites Audit Plan '!$G$8 -> 15 | S9: =+'Sites Audit Plan '!$F$8*'Sites Audit Plan '!$G$8 -> 15 | U9: =+'Sites Audit Plan '!$F$8*'Sites Audit Plan '!$G$8 -> 15 | V9: =+'Sites Audit Plan '!$F$8*'Sites Audit Plan '!$G$8 -> 15 | W9: =+'Sites Audit Plan '!$F$8*'Sites Audit Plan '!$G$8 -> 15 | X9: =+'Sites Audit Plan '!$F$8*'Sites Audit Plan '!$G$8 -> 15 | Y9: =+'Sites Audit Plan '!$F$8*'Sites Audit Plan '!$G$8 -> 15 | Z9: =+'Sites Audit Plan '!$F$8*'Sites Audit Plan '!$G$8 -> 15 | AB9: =+'Sites Audit Plan '!$F$8*'Sites Audit Plan '!$G$8 -> 15 | AC9: =+'Sites Audit Plan '!$F$8*'Sites Audit Plan '!$G$8 -> 15 | AD9: =+'Sites Audit Plan '!$F$8*'Sites Audit Plan '!$G$8 -> 15 | AE9: =+'Sites Audit Plan '!$F$8*'Sites Audit Plan '!$G$8 -> 15 | AF9: =+'Sites Audit Plan '!$F$8*'Sites Audit Plan '!$G$8 -> 15 | AG9: =+'Sites Audit Plan '!$F$8*'Sites Audit Plan '!$G$8 -> 15 | AI9: =+'Sites Audit Plan '!$F$8*'Sites Audit Plan '!$G$8 -> 15 | AJ9: =+'Sites Audit Plan '!$F$8*'Sites Audit Plan '!$G$8 -> 15 | AK9: =+'Sites Audit Plan '!$F$8*'Sites Audit Plan '!$G$8 -> 15 | AL9: =+'Sites Audit Plan '!$F$8*'Sites Audit Plan '!$G$8 -> 15 | AM9: =+'Sites Audit Plan '!$F$8*'Sites Audit Plan '!$G$8 -> 15 | AN9: =+'Sites Audit Plan '!$F$8*'Sites Audit Plan '!$G$8 -> 15 | AP9: =+'Sites Audit Plan '!$F$8*'Sites Audit Plan '!$G$8 -> 15 | AQ9: =+'Sites Audit Plan '!$F$8*'Sites Audit Plan '!$G$8 -> 15 | AR9: =+'Sites Audit Plan '!$F$8*'Sites Audit Plan '!$G$8 -> 15 | AS9: 10
A10: North | B10: =+'Sites Audit Plan '!D9 -> 132 | C10: =+'Sites Audit Plan '!E9 -> SBC2 | D10: =+'Sites Audit Plan '!H9 -> 24 | I10: =+'Sites Audit Plan '!$F$9*'Sites Audit Plan '!$G$9 -> 4 | J10: =+'Sites Audit Plan '!$F$9*'Sites Audit Plan '!$G$9 -> 4 | K10: =+'Sites Audit Plan '!$F$9*'Sites Audit Plan '!$G$9 -> 4 | L10: =+'Sites Audit Plan '!$F$9*'Sites Audit Plan '!$G$9 -> 4 | N10: =+'Sites Audit Plan '!$F$9*'Sites Audit Plan '!$G$9 -> 4 | O10: =+'Sites Audit Plan '!$F$9*'Sites Audit Plan '!$G$9 -> 4 | P10: =+'Sites Audit Plan '!$F$9*'Sites Audit Plan '!$G$9 -> 4 | Q10: =+'Sites Audit Plan '!$F$9*'Sites Audit Plan '!$G$9 -> 4 | R10: =+'Sites Audit Plan '!$F$9*'Sites Audit Plan '!$G$9 -> 4 | S10: =+'Sites Audit Plan '!$F$9*'Sites Audit Plan '!$G$9 -> 4 | U10: =+'Sites Audit Plan '!$F$9*'Sites Audit Plan '!$G$9 -> 4 | V10: =+'Sites Audit Plan '!$F$9*'Sites Audit Plan '!$G$9 -> 4 | W10: =+'Sites Audit Plan '!$F$9*'Sites Audit Plan '!$G$9 -> 4 | X10: =+'Sites Audit Plan '!$F$9*'Sites Audit Plan '!$G$9 -> 4 | Y10: =+'Sites Audit Plan '!$F$9*'Sites Audit Plan '!$G$9 -> 4 | Z10: =+'Sites Audit Plan '!$F$9*'Sites Audit Plan '!$G$9 -> 4 | AB10: =+'Sites Audit Plan '!$F$9*'Sites Audit Plan '!$G$9 -> 4 | AC10: =+'Sites Audit Plan '!$F$9*'Sites Audit Plan '!$G$9 -> 4 | AD10: =+'Sites Audit Plan '!$F$9*'Sites Audit Plan '!$G$9 -> 4 | AE10: =+'Sites Audit Plan '!$F$9*'Sites Audit Plan '!$G$9 -> 4 | AF10: =+'Sites Audit Plan '!$F$9*'Sites Audit Plan '!$G$9 -> 4 | AG10: =+'Sites Audit Plan '!$F$9*'Sites Audit Plan '!$G$9 -> 4 | AI10: =+'Sites Audit Plan '!$F$9*'Sites Audit Plan '!$G$9 -> 4 | AJ10: =+'Sites Audit Plan '!$F$9*'Sites Audit Plan '!$G$9 -> 4 | AK10: =+'Sites Audit Plan '!$F$9*'Sites Audit Plan '!$G$9 -> 4 | AL10: =+'Sites Audit Plan '!$F$9*'Sites Audit Plan '!$G$9 -> 4 | AM10: =+'Sites Audit Plan '!$F$9*'Sites Audit Plan '!$G$9 -> 4 | AN10: =+'Sites Audit Plan '!$F$9*'Sites Audit Plan '!$G$9 -> 4 | AP10: =+'Sites Audit Plan '!$F$9*'Sites Audit Plan '!$G$9 -> 4 | AQ10: =+'Sites Audit Plan '!$F$9*'Sites Audit Plan '!$G$9 -> 4 | AR10: =+'Sites Audit Plan '!$F$9*'Sites Audit Plan '!$G$9 -> 4 | AS10: =+'Sites Audit Plan '!$F$9*'Sites Audit Plan '!$G$9 -> 4 | AT10: =+'Sites Audit Plan '!$F$9*'Sites Audit Plan '!$G$9 -> 4
A11: North West | B11: =+'Sites Audit Plan '!D10 -> 192 | C11: =+'Sites Audit Plan '!E10 -> SBC3 | D11: =+'Sites Audit Plan '!H10 -> 30 | G11: =+'Sites Audit Plan '!$F$10*'Sites Audit Plan '!$G$10 -> 5 | H11: =+'Sites Audit Plan '!$F$10*'Sites Audit Plan '!$G$10 -> 5 | I11: =+'Sites Audit Plan '!$F$10*'Sites Audit Plan '!$G$10 -> 5 | J11: =+'Sites Audit Plan '!$F$10*'Sites Audit Plan '!$G$10 -> 5 | K11: =+'Sites Audit Plan '!$F$10*'Sites Audit Plan '!$G$10 -> 5 | L11: =+'Sites Audit Plan '!$F$10*'Sites Audit Plan '!$G$10 -> 5 | N11: =+'Sites Audit Plan '!$F$10*'Sites Audit Plan '!$G$10 -> 5 | O11: =+'Sites Audit Plan '!$F$10*'Sites Audit Plan '!$G$10 -> 5 | P11: =+'Sites Audit Plan '!$F$10*'Sites Audit Plan '!$G$10 -> 5 | Q11: =+'Sites Audit Plan '!$F$10*'Sites Audit Plan '!$G$10 -> 5 | R11: =+'Sites Audit Plan '!$F$10*'Sites Audit Plan '!$G$10 -> 5 | S11: =+'Sites Audit Plan '!$F$10*'Sites Audit Plan '!$G$10 -> 5 | U11: =+'Sites Audit Plan '!$F$10*'Sites Audit Plan '!$G$10 -> 5 | V11: =+'Sites Audit Plan '!$F$10*'Sites Audit Plan '!$G$10 -> 5 | W11: =+'Sites Audit Plan '!$F$10*'Sites Audit Plan '!$G$10 -> 5 | X11: =+'Sites Audit Plan '!$F$10*'Sites Audit Plan '!$G$10 -> 5 | Y11: =+'Sites Audit Plan '!$F$10*'Sites Audit Plan '!$G$10 -> 5 | Z11: =+'Sites Audit Plan '!$F$10*'Sites Audit Plan '!$G$10 -> 5 | AB11: =+'Sites Audit Plan '!$F$10*'Sites Audit Plan '!$G$10 -> 5 | AC11: =+'Sites Audit Plan '!$F$10*'Sites Audit Plan '!$G$10 -> 5 | AD11: =+'Sites Audit Plan '!$F$10*'Sites Audit Plan '!$G$10 -> 5 | AE11: =+'Sites Audit Plan '!$F$10*'Sites Audit Plan '!$G$10 -> 5 | AF11: =+'Sites Audit Plan '!$F$10*'Sites Audit Plan '!$G$10 -> 5 | AG11: =+'Sites Audit Plan '!$F$10*'Sites Audit Plan '!$G$10 -> 5 | AI11: =+'Sites Audit Plan '!$F$10*'Sites Audit Plan '!$G$10 -> 5 | AJ11: =+'Sites Audit Plan '!$F$10*'Sites Audit Plan '!$G$10 -> 5 | AK11: =+'Sites Audit Plan '!$F$10*'Sites Audit Plan '!$G$10 -> 5 | AL11: =+'Sites Audit Plan '!$F$10*'Sites Audit Plan '!$G$10 -> 5 | AM11: =+'Sites Audit Plan '!$F$10*'Sites Audit Plan '!$G$10 -> 5 | AN11: =+'Sites Audit Plan '!$F$10*'Sites Audit Plan '!$G$10 -> 5 | AP11: =+'Sites Audit Plan '!$F$10*'Sites Audit Plan '!$G$10 -> 5 | AQ11: =+'Sites Audit Plan '!$F$10*'Sites Audit Plan '!$G$10 -> 5 | AR11: =+'Sites Audit Plan '!$F$10*'Sites Audit Plan '!$G$10 -> 5 | AS11: =+'Sites Audit Plan '!$F$10*'Sites Audit Plan '!$G$10 -> 5 | AT11: =+'Sites Audit Plan '!$F$10*'Sites Audit Plan '!$G$10 -> 5 | AU11: =+'Sites Audit Plan '!$F$10*'Sites Audit Plan '!$G$10 -> 5 | AV11: =+'Sites Audit Plan '!$F$10*'Sites Audit Plan '!$G$10 -> 5 | AW11: =+'Sites Audit Plan '!$F$10*'Sites Audit Plan '!$G$10 -> 5 | AX11: 2
A12: South | B12: =+'Sites Audit Plan '!D11 -> 109 | C12: =+'Sites Audit Plan '!E11 -> SBC2 | D12: =+'Sites Audit Plan '!H11 -> 24 | G12: =+'Sites Audit Plan '!$F$11*'Sites Audit Plan '!$G$11 -> 4 | H12: =+'Sites Audit Plan '!$F$11*'Sites Audit Plan '!$G$11 -> 4 | I12: =+'Sites Audit Plan '!$F$11*'Sites Audit Plan '!$G$11 -> 4 | J12: =+'Sites Audit Plan '!$F$11*'Sites Audit Plan '!$G$11 -> 4 | K12: =+'Sites Audit Plan '!$F$11*'Sites Audit Plan '!$G$11 -> 4 | L12: =+'Sites Audit Plan '!$F$11*'Sites Audit Plan '!$G$11 -> 4 | N12: =+'Sites Audit Plan '!$F$11*'Sites Audit Plan '!$G$11 -> 4 | O12: =+'Sites Audit Plan '!$F$11*'Sites Audit Plan '!$G$11 -> 4 | P12: =+'Sites Audit Plan '!$F$11*'Sites Audit Plan '!$G$11 -> 4 | Q12: =+'Sites Audit Plan '!$F$11*'Sites Audit Plan '!$G$11 -> 4 | R12: =+'Sites Audit Plan '!$F$11*'Sites Audit Plan '!$G$11 -> 4 | S12: =+'Sites Audit Plan '!$F$11*'Sites Audit Plan '!$G$11 -> 4 | U12: =+'Sites Audit Plan '!$F$11*'Sites Audit Plan '!$G$11 -> 4 | V12: =+'Sites Audit Plan '!$F$11*'Sites Audit Plan '!$G$11 -> 4 | W12: =+'Sites Audit Plan '!$F$11*'Sites Audit Plan '!$G$11 -> 4 | X12: =+'Sites Audit Plan '!$F$11*'Sites Audit Plan '!$G$11 -> 4 | Y12: =+'Sites Audit Plan '!$F$11*'Sites Audit Plan '!$G$11 -> 4 | Z12: =+'Sites Audit Plan '!$F$11*'Sites Audit Plan '!$G$11 -> 4 | AB12: =+'Sites Audit Plan '!$F$11*'Sites Audit Plan '!$G$11 -> 4 | AC12: =+'Sites Audit Plan '!$F$11*'Sites Audit Plan '!$G$11 -> 4 | AD12: =+'Sites Audit Plan '!$F$11*'Sites Audit Plan '!$G$11 -> 4 | AE12: =+'Sites Audit Plan '!$F$11*'Sites Audit Plan '!$G$11 -> 4 | AF12: =+'Sites Audit Plan '!$F$11*'Sites Audit Plan '!$G$11 -> 4 | AG12: =+'Sites Audit Plan '!$F$11*'Sites Audit Plan '!$G$11 -> 4 | AI12: =+'Sites Audit Plan '!$F$11*'Sites Audit Plan '!$G$11 -> 4 | AJ12: =+'Sites Audit Plan '!$F$11*'Sites Audit Plan '!$G$11 -> 4 | AK12: =+'Sites Audit Plan '!$F$11*'Sites Audit Plan '!$G$11 -> 4 | AL12: 1
A13: South West | B13: =+'Sites Audit Plan '!D12 -> 234 | C13: =+'Sites Audit Plan '!E12 -> SBC3 | D13: =+'Sites Audit Plan '!H12 -> 60 | G13: =+'Sites Audit Plan '!$F$12*'Sites Audit Plan '!$G$12 -> 10 | H13: =+'Sites Audit Plan '!$F$12*'Sites Audit Plan '!$G$12 -> 10 | I13: =+'Sites Audit Plan '!$F$12*'Sites Audit Plan '!$G$12 -> 10 | J13: =+'Sites Audit Plan '!$F$12*'Sites Audit Plan '!$G$12 -> 10 | K13: =+'Sites Audit Plan '!$F$12*'Sites Audit Plan '!$G$12 -> 10 | L13: =+'Sites Audit Plan '!$F$12*'Sites Audit Plan '!$G$12 -> 10 | N13: =+'Sites Audit Plan '!$F$12*'Sites Audit Plan '!$G$12 -> 10 | O13: =+'Sites Audit Plan '!$F$12*'Sites Audit Plan '!$G$12 -> 10 | P13: =+'Sites Audit Plan '!$F$12*'Sites Audit Plan '!$G$12 -> 10 | Q13: =+'Sites Audit Plan '!$F$12*'Sites Audit Plan '!$G$12 -> 10 | R13: =+'Sites Audit Plan '!$F$12*'Sites Audit Plan '!$G$12 -> 10 | S13: =+'Sites Audit Plan '!$F$12*'Sites Audit Plan '!$G$12 -> 10 | U13: =+'Sites Audit Plan '!$F$12*'Sites Audit Plan '!$G$12 -> 10 | V13: =+'Sites Audit Plan '!$F$12*'Sites Audit Plan '!$G$12 -> 10 | W13: =+'Sites Audit Plan '!$F$12*'Sites Audit Plan '!$G$12 -> 10 | X13: =+'Sites Audit Plan '!$F$12*'Sites Audit Plan '!$G$12 -> 10 | Y13: =+'Sites Audit Plan '!$F$12*'Sites Audit Plan '!$G$12 -> 10 | Z13: =+'Sites Audit Plan '!$F$12*'Sites Audit Plan '!$G$12 -> 10 | AB13: =+'Sites Audit Plan '!$F$12*'Sites Audit Plan '!$G$12 -> 10 | AC13: =+'Sites Audit Plan '!$F$12*'Sites Audit Plan '!$G$12 -> 10 | AD13: =+'Sites Audit Plan '!$F$12*'Sites Audit Plan '!$G$12 -> 10 | AE13: =+'Sites Audit Plan '!$F$12*'Sites Audit Plan '!$G$12 -> 10 | AF13: =+'Sites Audit Plan '!$F$12*'Sites Audit Plan '!$G$12 -> 10 | AG13: 4
A14: West | B14: =+'Sites Audit Plan '!D13 -> 262 | C14: =+'Sites Audit Plan '!E13 -> SBC1 | D14: =+'Sites Audit Plan '!H13 -> 48 | G14: =+'Sites Audit Plan '!$F$13*'Sites Audit Plan '!$G$13 -> 8 | H14: =+'Sites Audit Plan '!$F$13*'Sites Audit Plan '!$G$13 -> 8 | I14: =+'Sites Audit Plan '!$F$13*'Sites Audit Plan '!$G$13 -> 8 | J14: =+'Sites Audit Plan '!$F$13*'Sites Audit Plan '!$G$13 -> 8 | K14: =+'Sites Audit Plan '!$F$13*'Sites Audit Plan '!$G$13 -> 8 | L14: =+'Sites Audit Plan '!$F$13*'Sites Audit Plan '!$G$13 -> 8 | N14: =+'Sites Audit Plan '!$F$13*'Sites Audit Plan '!$G$13 -> 8 | O14: =+'Sites Audit Plan '!$F$13*'Sites Audit Plan '!$G$13 -> 8 | P14: =+'Sites Audit Plan '!$F$13*'Sites Audit Plan '!$G$13 -> 8 | Q14: =+'Sites Audit Plan '!$F$13*'Sites Audit Plan '!$G$13 -> 8 | R14: =+'Sites Audit Plan '!$F$13*'Sites Audit Plan '!$G$13 -> 8 | S14: =+'Sites Audit Plan '!$F$13*'Sites Audit Plan '!$G$13 -> 8 | U14: =+'Sites Audit Plan '!$F$13*'Sites Audit Plan '!$G$13 -> 8 | V14: =+'Sites Audit Plan '!$F$13*'Sites Audit Plan '!$G$13 -> 8 | W14: =+'Sites Audit Plan '!$F$13*'Sites Audit Plan '!$G$13 -> 8 | X14: =+'Sites Audit Plan '!$F$13*'Sites Audit Plan '!$G$13 -> 8 | Y14: =+'Sites Audit Plan '!$F$13*'Sites Audit Plan '!$G$13 -> 8 | Z14: =+'Sites Audit Plan '!$F$13*'Sites Audit Plan '!$G$13 -> 8 | AB14: =+'Sites Audit Plan '!$F$13*'Sites Audit Plan '!$G$13 -> 8 | AC14: =+'Sites Audit Plan '!$F$13*'Sites Audit Plan '!$G$13 -> 8 | AD14: =+'Sites Audit Plan '!$F$13*'Sites Audit Plan '!$G$13 -> 8 | AE14: =+'Sites Audit Plan '!$F$13*'Sites Audit Plan '!$G$13 -> 8 | AF14: =+'Sites Audit Plan '!$F$13*'Sites Audit Plan '!$G$13 -> 8 | AG14: =+'Sites Audit Plan '!$F$13*'Sites Audit Plan '!$G$13 -> 8 | AI14: =+'Sites Audit Plan '!$F$13*'Sites Audit Plan '!$G$13 -> 8 | AJ14: =+'Sites Audit Plan '!$F$13*'Sites Audit Plan '!$G$13 -> 8 | AK14: =+'Sites Audit Plan '!$F$13*'Sites Audit Plan '!$G$13 -> 8 | AL14: =+'Sites Audit Plan '!$F$13*'Sites Audit Plan '!$G$13 -> 8 | AM14: =+'Sites Audit Plan '!$F$13*'Sites Audit Plan '!$G$13 -> 8 | AN14: =+'Sites Audit Plan '!$F$13*'Sites Audit Plan '!$G$13 -> 8 | AP14: =+'Sites Audit Plan '!$F$13*'Sites Audit Plan '!$G$13 -> 8 | AQ14: =+'Sites Audit Plan '!$F$13*'Sites Audit Plan '!$G$13 -> 8 | AR14: 6
A15: Weekly Target | D15: =SUBTOTAL(9,D5:D14) -> 198 | E15: =SUBTOTAL(9,E5:E14) -> 15 | G15: =SUBTOTAL(9,G5:G14) -> 19 | H15: =SUBTOTAL(9,H5:H14) -> 23 | I15: =SUBTOTAL(9,I5:I14) -> 27 | J15: =SUBTOTAL(9,J5:J14) -> 33 | K15: =SUBTOTAL(9,K5:K14) -> 33 | L15: =SUBTOTAL(9,L5:L14) -> 33 | N15: =SUBTOTAL(9,N5:N14) -> 33 | O15: =SUBTOTAL(9,O5:O14) -> 33 | P15: =SUBTOTAL(9,P5:P14) -> 33 | Q15: =SUBTOTAL(9,Q5:Q14) -> 33 | R15: =SUBTOTAL(9,R5:R14) -> 33 | S15: =SUBTOTAL(9,S5:S14) -> 33 | U15: =SUBTOTAL(9,U5:U14) -> 33 | V15: =SUBTOTAL(9,V5:V14) -> 33 | W15: =SUBTOTAL(9,W5:W14) -> 33 | X15: =SUBTOTAL(9,X5:X14) -> 33 | Y15: =SUBTOTAL(9,Y5:Y14) -> 33 | Z15: =SUBTOTAL(9,Z5:Z14) -> 33 | AB15: =SUBTOTAL(9,AB5:AB14) -> 33 | AC15: =SUBTOTAL(9,AC5:AC14) -> 33 | AD15: =SUBTOTAL(9,AD5:AD14) -> 33 | AE15: =SUBTOTAL(9,AE5:AE14) -> 33 | AF15: =SUBTOTAL(9,AF5:AF14) -> 33 | AG15: =SUBTOTAL(9,AG5:AG14) -> 33 | AI15: =SUBTOTAL(9,AI5:AI14) -> 33 | AJ15: =SUBTOTAL(9,AJ5:AJ14) -> 33 | AK15: =SUBTOTAL(9,AK5:AK14) -> 33 | AL15: =SUBTOTAL(9,AL5:AL14) -> 33 | AM15: =SUBTOTAL(9,AM5:AM14) -> 33 | AN15: =SUBTOTAL(9,AN5:AN14) -> 33 | AP15: =SUBTOTAL(9,AP5:AP14) -> 31 | AQ15: =SUBTOTAL(9,AQ5:AQ14) -> 29 | AR15: =SUBTOTAL(9,AR5:AR14) -> 29 | AS15: =SUBTOTAL(9,AS5:AS14) -> 21 | AT15: =SUBTOTAL(9,AT5:AT14) -> 14 | AU15: =SUBTOTAL(9,AU5:AU14) -> 9 | AV15: =SUBTOTAL(9,AV5:AV14) -> 4 | AW15: =SUBTOTAL(9,AW5:AW14) -> 0 | ... AZ15: =SUBTOTAL(9,AZ5:AZ14) -> 0
A16: Achieved
A17: GAP
A19: Legend : | C19: Free day
C20: Travelling time
C21: Delivery period
C22: ROM1 (IVAN)
C23: ROM2 (ROSTAND)

Sheet Sites Audit Plan Region 1
F1: =+SUBTOTAL(3,F3:F2443) -> 1225 | G1: =+SUBTOTAL(3,G3:G2443) -> 1225 | L1: =+SUBTOTAL(3,L3:L2443) -> 1225 | P1: PIP/Region 1
A2: No | B2: Operator Site ID | C2: IHS ID | D2: Operator Site ID | E2: State | F2: Site Name | G2: Access Status | H2: Site Configuration | I2: Clusters | J2: Division | K2: Sub-Division | L2: Town | M2: Latitude | N2: Longitude | O2: Site Type | P2: SBC Name | Q2: Weeks | R2: Dates
A3: 322 | B3: OST_092 | C3: IHS_NGD_096 | D3: OST_092 | E3: Adamawa | F3: Taram-FH | G3: Normal Access | H3: Indoor | I3: Tibati | J3: TIBATI | K3: BANYO | L3: Banyo | M3: 6.706611 | N3: 11.779889 | O3: Greenfield
A4: 326 | B4: CTR_303 | C4: IHS_YND_477 | D4: CTR_303 | E4: Adamawa | F4: Mbam | G4: Normal Access | H4: Outdoor | I4: Tibati | J4: TIBATI | K4: YOKO | L4: Banyo | M4: 5.99235 | N4: 12.391995 | O4: Greenfield
A5: 327 | B5: T1821 | C5: IHS_NGD_102 | D5: T1821 | E5: Adamawa | F5: Mayo Baleo Ville | G5: Normal Access | H5: Outdoor | I5: Tibati | J5: TIBATI | K5: MAYO BALEO | L5: Banyo | M5: 7.657583 | N5: 12.334389 | O5: Greenfield
A6: 328 | B6: CTR_301 | C6: IHS_YND_460 | D6: CTR_301 | E6: Center | F6: Matsari | G6: Normal Access | H6: Outdoor | I6: N'TUI | J6: MBAM ET KIM | K6: YOKO | L6: Banyo | M6: 5.37011 | N6: 12.271541 | O6: Greenfield
A7: 329 | B7: CTR_302 | C7: IHS_YND_476 | D7: CTR_302 | E7: Adamawa | F7: Doume-Centre | G7: Normal Access | H7: Outdoor | I7: Tibati | J7: TIBATI | K7: YOKO | L7: Banyo | M7: 5.89461 | N7: 12.28128 | O7: Greenfield
A8: 330 | B8: ADM_128 | C8: IHS_NGD_228 | D8: ADM_128 | E8: Adamawa | F8: Dogba-Ngd | G8: Normal Access | H8: Outdoor | I8: Tibati | J8: TIBATI | K8: MAYO BALEO | L8: Banyo | M8: 7.646936 | N8: 12.389979 | O8: Greenfield
A9: 331 | B9: T0812 | C9: IHS_NGD_092 | D9: T0812 | E9: Adamawa | F9: Darasalam | G9: Normal Access | H9: Outdoor | I9: Tibati | J9: TIBATI | K9: BANYO | L9: Banyo | M9: 6.656193 | N9: 12.061108 | O9: Greenfield
A10: 334 | B10: T0379 | C10: IHS_YND_473 | D10: T0379 | E10: Center | F10: Yoko | G10: Normal Access | H10: Indoor | I10: N'TUI | J10: MBAM ET KIM | K10: YOKO | L10: Banyo | M10: 5.539178 | N10: 12.317745 | O10: Greenfield
A11: 335 | B11: T0723 | C11: IHS_NGD_091 | D11: T0723 | E11: Adamawa | F11: Mbakaou | G11: Normal Access | H11: Outdoor | I11: Tibati | J11: TIBATI | K11: TIBATI | L11: Banyo | M11: 6.31108 | N11: 12.7965 | O11: Greenfield
A12: 338 | B12: CTR_335 | C12: IHS_YND_474 | D12: CTR_335 | E12: Center | F12: Yoko | G12: Normal Access | H12: Outdoor | I12: N'TUI | J12: MBAM ET KIM | K12: YOKO | L12: Banyo | M12: 5.539167 | N12: 12.317806 | O12: Greenfield
A13: 339 | B13: T0431 | C13: IHS_NGD_094 | D13: T0431 | E13: Adamawa | F13: Banyo Town | G13: Normal Access | H13: Indoor | I13: Tibati | J13: TIBATI | K13: BANYO | L13: Banyo | M13: 6.74914 | N13: 11.80564 | O13: Rooftop
A14: 340 | B14: T0324 | C14: IHS_NGD_095 | D14: T0324 | E14: Adamawa | F14: Banyo | G14: Normal Access | H14: Indoor | I14: Tibati | J14: TIBATI | K14: BANYO | L14: Banyo | M14: 6.708 | N14: 11.779 | O14: Greenfield
... A38: 372 | B38: T1895 | C38: IHS_NGD_106 | D38: T1895 | E38: Adamawa | F38: Tibati 3 | G38: Normal Access | H38: Outdoor | I38: Tibati | J38: TIBATI | K38: TIBATI | L38: Banyo | M38: 6.471961 | N38: 12.623745 | O38: Greenfield
A39: 373 | B39: T2058 | C39: IHS_NGD_107 | D39: T2058 | E39: Adamawa | F39: Galim Tignere 2 | G39: Normal Access | H39: Outdoor | J39: FARO ET DEO | K39: GALIM TIGNERE | L39: Banyo | M39: 7.097953 | N39: 12.473915 | O39: Greenfield
A40: 374 | B40: EST_116 | C40: IHS_BER_160 | D40: EST_116 | E40: East | F40: Tongo Ngandinma | G40: Normal Access | H40: Outdoor | I40: Garoua Boulai | J40: LOM-ET-DJEREM | K40: Goura | L40: Bertoua | M40: 5.184827 | N40: 14.000816 | O40: Greenfield
A41: 375 | B41: T1808 | C41: IHS_BER_105 | D41: T1808 | E41: East | F41: SFID NDENG | G41: Normal Access | H41: Outdoor | I41: Yokadouma | J41: Yokadouma (Mboumba et Ngoko) | K41: Sfdi deng | L41: Bertoua | M41: 3.78637 | N41: 14.993912 | O41: Greenfield
A42: 376 | B42: T2143 | C42: IHS_BER_106 | D42: T2143 | E42: East | F42: SALAPOUMBE VILLE | G42: Normal Access | H42: Outdoor | I42: Yokadouma | J42: Yokadouma (Mboumba et Ngoko) | K42: Salapoumbe | L42: Bertoua | M42: 2.636417 | N42: 15.368528 | O42: Greenfield
A43: 377 | B43: EST_114 | C43: IHS_BER_159 | D43: EST_114 | E43: East | F43: Ouli | G43: Normal Access | H43: Outdoor | I43: Batouri | J43: Batouri (Kadey) | K43: Kette | L43: Bertoua | M43: 5.19977 | N43: 14.555227 | O43: Greenfield
A44: 378 | B44: T0591 | C44: IHS_YND_458 | D44: T0591 | E44: East | F44: Minta | G44: Normal Access | H44: Outdoor | I44: Nanga Eboko | J44: HAUTE-SANAGA | K44: Minta | L44: Bertoua | M44: 4.565895 | N44: 12.831797 | O44: Greenfield
A45: 379 | B45: T2133 | C45: IHS_BER_104 | D45: T2133 | E45: East | F45: MINDOUROU GRUMCAM | G45: Normal Access | H45: Outdoor | I45: Batouri | J45: Batouri (Kadey) | K45: Mindourou Grumcam | L45: Bertoua | M45: 4.102 | N45: 14.574639 | O45: Greenfield
A46: 380 | B46: T0916 | C46: IHS_SGM_024 | D46: T0916 | E46: South | F46: Meveme | G46: Normal Access | H46: Outdoor | I46: Djoum | J46: DJA-ET-LOBO | K46: COMMUNE DE MINTOM | L46: Bertoua | M46: 2.68931 | N46: 13.18544 | O46: Greenfield
A47: 381 | B47: EST_074 | C47: IHS_BER_050 | D47: EST_074 | E47: East | F47: Mazabe | G47: Normal Access | H47: Outdoor | I47: Abong Mbang | J47: HAUT-NYONG | K47: ABONGMBANG | L47: Bertoua | M47: 4.010291 | N47: 13.004276 | O47: Greenfield
A48: 382 | B48: EST_072 | C48: IHS_BER_015 | D48: EST_072 | E48: East | F48: Longtimbi | G48: Normal Access | H48: Outdoor | I48: Bertoua | J48: LOM-ET-DJEREM | K48: Bertoua 1 | L48: Bertoua | M48: 4.47275 | N48: 13.620556 | O48: Greenfield
A49: 383 | B49: EST_071 | C49: IHS_BER_023 | D49: EST_071 | E49: East | F49: Kouen | G49: Normal Access | H49: Outdoor | I49: Abong Mbang | J49: HAUT-NYONG | K49: DIMAKO | L49: Bertoua | M49: 4.312472 | N49: 13.507417 | O49: Greenfield
A50: 384 | B50: T1222 | C50: IHS_BER_014 | D50: T1222 | E50: East | F50: KOUBA | G50: Normal Access | H50: Outdoor | I50: Bertoua | J50: LOM-ET-DJEREM | K50: Mandjou | L50: Bertoua | M50: 4.636162 | N50: 13.778363 | O50: Greenfield
A51: 385 | B51: EST_115 | C51: IHS_BER_152 | D51: EST_115 | E51: East | F51: Kika | G51: Normal Access | H51: Outdoor | I51: Yokadouma | J51: Yokadouma (Mboumba et Ngoko) | K51: Moloundou | L51: Bertoua | M51: 2.2779 | N51: 15.34802 | O51: Greenfield
... A331: 1328 | B331: T0138 | C331: IHS_EBO_021 | D331: T0138 | E331: South | F331: Ambam | G331: Normal Access | H331: Indoor | I331: AMBAM | J331: NTEM | K331: AMBAM | L331: Kribi & Edea | M331: 2.386327 | N331: 11.264132 | O331: Greenfield
A332: 1333 | B332: T2080 | C332: IHS_KRI_030 | D332: T2080 | E332: SOUTH | F332: KRIBI CHEFFERIE MAOVE | G332: Normal Access | H332: Outdoor | J332: OCEAN | K332: KRIBI II | L332: Kribi & Edea | M332: 2.962823 | N332: 9.92119 | O332: Greenfield
A333: 1479 | B333: EXN_127 | C333: IHS_MAR_307 | D333: EXN_127 | E333: Far North | F333: Wina | G333: Normal Access | H333: Outdoor | I333: Yagoua | J333: Mayo-DANAY | K333: Wina | L333: Maroua | M333: 10.068 | N333: 15.2184 | O333: Greenfield
A334: 1480 | B334: T2148 | C334: IHS_MAR_216 | D334: T2148 | E334: Far North | F334: TOULOUM | G334: Normal Access | H334: Outdoor | I334: Yagoua | J334: Mayo-kani | K334: Touloum | L334: Maroua | M334: 10.18041 | N334: 14.83565 | O334: Greenfield
A335: 1481 | B335: T2013 | C335: IHS_MAR_209 | D335: T2013 | E335: Far North | F335: ROUA | G335: Normal Access | H335: Outdoor | I335: Yagoua | J335: Mayo-Tsanaga | K335: Soulédé-Roua | L335: Maroua | M335: 10.75975 | N335: 13.967944 | O335: Greenfield
A336: 1482 | B336: EXN_073 | C336: IHS_MAR_049 | D336: EXN_073 | E336: Far North | F336: Ndoukoula | G336: Normal Access | H336: Outdoor | I336: Yagoua | J336: Mayo-Tsanaga | K336: Ndoukoula | L336: Maroua | M336: 10.278333 | N336: 14.036917 | O336: Greenfield
A337: 1483 | B337: EXN_136 | C337: IHS_MAR_351 | D337: EXN_136 | E337: North | F337: Mousgoy | G337: Normal Access | H337: Outdoor | I337: Garoua 2 | J337: MAYO- LOUTI | K337: Guider | L337: Maroua | M337: 10.89456 | N337: 13.89456 | O337: Greenfield
A338: 1484 | B338: EXN_175 | C338: IHS_MAR_368 | D338: EXN_175 | E338: Far North | F338: Moude | G338: Normal Access | H338: Outdoor | I338: Yagoua | J338: Mayo-Tsanaga | K338: Mogode | L338: Maroua | M338: 10.42773 | N338: 13.56652 | O338: Greenfield
A339: 1485 | B339: EXN_186 | C339: IHS_MAR_342 | D339: EXN_186 | E339: Far North | F339: Mouda | G339: Normal Access | H339: Outdoor | I339: Yagoua | J339: Mayo-kani | K339: Moutourwa | L339: Maroua | M339: 10.358115 | N339: 14.232395 | O339: Greenfield
A340: 1486 | B340: T1403 | C340: IHS_MAR_044 | D340: T1403 | E340: Far North | F340: Mokong | G340: Normal Access | H340: Outdoor | I340: Yagoua | J340: Mayo-kani | K340: Mokolo | L340: Maroua | M340: 10.595139 | N340: 13.994444 | O340: Greenfield
A341: 1487 | B341: T0880 | C341: IHS_MAR_032 | D341: T0880 | E341: Far North | F341: Meskin | G341: Normal Access | H341: Outdoor | I341: Maroua | J341: Diamare | K341: Maroua1 | L341: Maroua | M341: 10.564 | N341: 14.271 | O341: Greenfield
A342: 1488 | B342: EXN_169 | C342: IHS_MAR_341 | D342: EXN_169 | E342: Far North | F342: MEME II | G342: Normal Access | H342: Outdoor | I342: Maroua | J342: Mayo-Sava | K342: Mora | L342: Maroua | M342: 10.970418 | N342: 14.232792 | O342: Greenfield
...

Sheet Sites Audit Plan Region 2
F1: =+SUBTOTAL(3,F3:F2443) -> 1216 | G1: =+SUBTOTAL(3,G3:G2443) -> 1216 | L1: =+SUBTOTAL(3,L3:L2443) -> 1216 | P1: PIP/Region 2
A2: No | B2: Operator Site ID | C2: IHS ID | D2: Operator Site ID | E2: State | F2: Site Name | G2: Access Status | H2: Site Configuration | I2: Clusters | J2: Division | K2: Sub-Division | L2: Town | M2: Latitude | N2: Longitude | O2: Site Type | P2: SBC Name | Q2: Weeks | R2: Dates
A3: 1 | B3: T2781 | C3: IHS_BAF_105 | D3: T2781 | E3: West | F3: PENKA MICHEL | G3: Normal Access | H3: Outdoor | I3: Bafoussam1 | J3: MENOUA | K3: PENKA MICHEL | L3: Bafoussam | M3: 5.46817 | N3: 10.2413 | O3: Greenfield
A4: 2 | B4: CTR_297 | C4: IHS_YND_463 | D4: CTR_297 | E4: West | F4: Nomale | G4: Normal Access | H4: Outdoor | I4: Bafia | J4: Mbam et inoubou | K4: Ndikinimeki | L4: Bafoussam | M4: 4.7715 | N4: 10.90632 | O4: Greenfield
A5: 3 | B5: OST_219 | C5: IHS_FBN_055 | D5: OST_219 | E5: West | F5: Ngbetnsouen | G5: Normal Access | H5: Outdoor | I5: Foumbot | J5: Noun | K5: Kouoptamo | L5: Bafoussam | M5: 5.63442 | N5: 10.53025 | O5: Greenfield
A6: 4 | B6: CTR_054 | C6: IHS_YND_445 | D6: CTR_054 | E6: West | F6: Ndoussan | G6: Normal Access | H6: Indoor | I6: Bafia | J6: Mbam et inoubou | K6: Kon-yambetta | L6: Bafoussam | M6: 4.822962 | N6: 11.175922 | O6: Greenfield
A7: 5 | B7: OST_207 | C7: IHS_FBN_046 | D7: OST_207 | E7: West | F7: Ndoumken | G7: Normal Access | H7: Outdoor | I7: Foumbot | J7: Noun | K7: Kouoptamo | L7: Bafoussam | M7: 5.65799 | N7: 10.56229 | O7: Greenfield
A8: 6 | B8: OST_201 | C8: IHS_FBN_053 | D8: OST_201 | E8: West | F8: Mantoum Ville | G8: Normal Access | H8: Outdoor | I8: Foumban | J8: Noun | K8: Malantouen | L8: Bafoussam | M8: 5.656112 | N8: 11.172957 | O8: Greenfield
A9: 7 | B9: T1640 | C9: IHS_FBN_028 | D9: T1640 | E9: West | F9: Koupa Matapit | G9: Normal Access | H9: Outdoor | I9: Foumbot | J9: Noun | K9: Foumban | L9: Bafoussam | M9: 5.772444 | N9: 10.791806 | O9: Greenfield
A10: 8 | B10: T2028 | C10: IHS_MBD_014 | D10: T2028 | E10: West | F10: GALIM EEC | G10: Red Zone | H10: Outdoor | I10: Bafoussam1 | J10: BAMBOUTOUS | K10: Galim | L10: Bafoussam | M10: 5.682028 | N10: 10.366139 | O10: Greenfield
